<?xml version="1.0"?>

<robot name="3DOF">

    <!-- Base -->
    <link name="base">
        <visual>
            <geometry>
                <box size="0.1 0.1 0.1"/>
            </geometry>
        </visual>
<collision>
    <geometry>
        <cylinder radius="0.05" length="0.1"/>
    </geometry>
</collision>

<inertial>
    <mass value="2.0"/>
    <inertia
        ixx="0.01"
        ixy="0.0"
        ixz="0.0"
        iyy="0.01"
        iyz="0.0"
        izz="0.01"/>
</inertial>
    </link>

<link name="world"/>

<joint name="world_to_base" type="fixed">
    <parent link="world"/>
    <child link="base"/>
    <origin xyz="0 0 0"/>
</joint>
    <!-- Link1 -->
    <link name="link1">
        <visual>
            <origin xyz="0.25 0 0"/>
            <geometry>
                <box size="0.5 0.05 0.05"/>
            </geometry>
        </visual>
<collision>
    <geometry>
        <cylinder radius="0.03" length="0.5"/>
    </geometry>
</collision>

<inertial>
    <mass value="1.0"/>

    <inertia
        ixx="0.01"
        ixy="0.0"
        ixz="0.0"
        iyy="0.01"
        iyz="0.0"
        izz="0.01"/>
</inertial>
    </link>

    <!-- Joint1 -->
    <joint name="joint1" type="revolute">
        <parent link="base"/>
        <child link="link1"/>

        <origin xyz="0 0 0.05"/>

        <axis xyz="0 0 1"/>

        <limit
            lower="-3.14"
            upper="3.14"
            effort="10"
            velocity="1"/>
    </joint>

    <!-- Link2 -->
    <link name="link2">
        <visual>
            <origin xyz="0.20 0 0"/>
            <geometry>
                <box size="0.4 0.05 0.05"/>
            </geometry>
        </visual>
<collision>
    <geometry>
        <cylinder radius="0.03" length="0.4"/>
    </geometry>
</collision>

<inertial>
    <mass value="1.0"/>
    <inertia
        ixx="0.01"
        ixy="0.0"
        ixz="0.0"
        iyy="0.01"
        iyz="0.0"
        izz="0.01"/>
</inertial>
    </link>

    <!-- Joint2 -->
    <joint name="joint2" type="revolute">
        <parent link="link1"/>
        <child link="link2"/>

        <origin xyz="0.5 0 0"/>

        <axis xyz="0 0 1"/>

        <limit
            lower="-3.14"
            upper="3.14"
            effort="10"
            velocity="1"/>
    </joint>

    <!-- Link3 -->
    <link name="link3">
        <visual>
            <origin xyz="0.15 0 0"/>
            <geometry>
                <box size="0.3 0.05 0.05"/>
            </geometry>
        </visual>
<collision>
    <geometry>
        <cylinder radius="0.03" length="0.3"/>
    </geometry>
</collision>

<inertial>
    <mass value="1.0"/>
    <inertia
        ixx="0.01"
        ixy="0.0"
        ixz="0.0"
        iyy="0.01"
        iyz="0.0"
        izz="0.01"/>
</inertial>
    </link>

    <!-- Joint3 -->
    <joint name="joint3" type="revolute">
        <parent link="link2"/>
        <child link="link3"/>

        <origin xyz="0.4 0 0"/>

        <axis xyz="0 0 1"/>

        <limit
            lower="-3.14"
            upper="3.14"
            effort="10"
            velocity="1"/>
    </joint>

    <!-- End Effector -->
    <link name="ee_link">

    <collision>
        <geometry>
            <sphere radius="0.02"/>
        </geometry>
    </collision>

    <inertial>
        <mass value="0.1"/>
        <inertia
            ixx="0.001"
            ixy="0.0"
            ixz="0.0"
            iyy="0.001"
            iyz="0.0"
            izz="0.001"/>
    </inertial>

</link>

   <joint name="ee_joint" type="fixed">
    <parent link="link3"/>
    <child link="ee_link"/>

    <origin xyz="0.3 0 0"/>
</joint>

<ros2_control name="GazeboSystem" type="system">

    <hardware>
        <plugin>gz_ros2_control/GazeboSimSystem</plugin>
    </hardware>

    <joint name="joint1">
        <command_interface name="position"/>
        <state_interface name="position"/>
        <state_interface name="velocity"/>
    </joint>

    <joint name="joint2">
        <command_interface name="position"/>
        <state_interface name="position"/>
        <state_interface name="velocity"/>
    </joint>

    <joint name="joint3">
        <command_interface name="position"/>
        <state_interface name="position"/>
        <state_interface name="velocity"/>
    </joint>

</ros2_control>
<gazebo>
    <plugin
        filename="libgz_ros2_control-system.so"
        name="gz_ros2_control::GazeboSimROS2ControlPlugin">

        <parameters>
            /home/giri/arm_ik_ros2_ws/src/arm_ik_description/config/controllers.yaml
        </parameters>

    </plugin>
</gazebo>
</robot>
